#第8章 异常
## 8.1 异常是什么
Python使用异常对象表示异常状态，出错的时候引发异常，如果异常没有被处理，程序将终止并显示一条错误信息（traceback）  
每个异常都是某个类的实例。

## 8.2 让事情沿你指定的轨道出错
出错时，Python会自动引发异常。我们也可以自主地引发异常、创建异常。
### 8.2.1 raise语句
要引发异常，可以使用raise语句，后面跟一个异常类（必须是Exception的子类）或实例。  
将类作为参数的时候，会自动创建一个实例。
```python
# 直接使用类作为参数
raise Exception

Traceback (most recent call last):
File "E:/zjx/PycharmProjects/LearnPython/BeginningPython/chapter8/exception_test.py", line 9, in <module>
raise Exception
Exception
```
```python
# 使用异常类的实例作为参数
class MyException(Exception):
    pass

my_exception = MyException()
raise my_exception

Traceback (most recent call last):
File "E:/zjx/PycharmProjects/LearnPython/BeginningPython/chapter8/exception_test.py", line 14, in <module>
raise my_exception
__main__.MyException
```
内置的异常类

|类名|描述|
|----|----|
|Exception          |几乎所有的异常类都是从它派生而来的|
|AttributeError     |引用属性或给它赋值失败时引发|
|OSError            |操作系统不能执行指定的任务（如打开文件）时引发，有多个子类|
|IndexError         |使用序列中不存在的索引时引发，为LookupError的子类|
|KeyError           |使用映射中不存在的键时引发，为LookupError的子类|
|NameError          |找不到名称（变量）时引发|
|SyntaxError        |代码不正确时引发|
|TypeError          |将内置操作或函数用于类型不正确的对象时引发|
|ValueError         |将内置操作或函数用于这样的对象时引发：其类型正确但包含的值不合适|
|ZeroDivisionError  |在除法或求模运算的第二个参数为零时引发|

### 8.2.2  自定义异常类
自定义异常类必须直接或间接地继承Exception
```python
class MyException(Exception):
    pass
```

## 8.3 捕获异常
使用try/except语句
```python
try:
    x = int(input("请输入x"))
    y = int(input("请输入y"))
    print(x / y)
except ZeroDivisionError:
    print("y不能为0")
```
> 注意：异常从函数传播到调用函数的地方。如果在这里也没有被捕获，异常将接着向顶层传播。

### 8.3.1 不用提供参数
捕获异常之后，可以重新引发他，可以使用raise且不提供任何参数
```python
class MuffledCalcultor:
    muffled = False

    def calc(self, exp):
        try:
            return eval(exp)
        except ZeroDivisionError:
            if self.muffled:
                print('除0不合法')
            else:
                raise


calculator = MuffledCalcultor()
print(calculator.calc('10/2'))  # 5.0
print(calculator.calc('10/0'))  # 抛出异常

calculator.muffled = True
print(calculator.calc('10/0'))  # 除0是不合法的
```
可以引发别的异常
```python
try:
    1/0
except ZeroDivisionError:
    raise ValueError


Traceback (most recent call last):
File "E:/zjx/PycharmProjects/LearnPython/BeginningPython/chapter8/exception_test.py", line 18, in <module>
1/0
ZeroDivisionError: division by zero

During handling of the above exception, another exception occurred:

Traceback (most recent call last):
File "E:/zjx/PycharmProjects/LearnPython/BeginningPython/chapter8/exception_test.py", line 20, in <module>
raise ValueError
ValueError
```
使用raise from
```python
# from None禁用上下文
try:
    1/0
except ZeroDivisionError:
    raise ValueError from None


Traceback (most recent call last):
File "E:/zjx/PycharmProjects/LearnPython/BeginningPython/chapter8/exception_test.py", line 20, in <module>
raise ValueError from None
ValueError
```

### 8.3.2 多个except语句
```python
try:
    x = int(input("请输入x"))
    y = int(input("请输入y"))
    print(x / y)
except ZeroDivisionError:
    print("y不能为0")
except ValueError:
    print("输入内容无法转换为int")
```

### 8.3.3 一箭双雕
一个except语句可以捕获多种异常，将要捕获的异常放在一个元组里
```python
try:
    x = int(input("请输入x"))
    y = int(input("请输入y"))
    print(x / y)
except (ZeroDivisionError, NameError, ValueError):
    print("出异常了")
```
### 8.3.4 捕获对象
使用as来获取异常对象本身
```python
try:
    x = int(input("请输入x"))
    y = int(input("请输入y"))
    print(x / y)
except (ZeroDivisionError, NameError, ValueError) as e:
    print(e)
```

### 8.3.5 一网打尽
如果想捕获所有的异常，可以在except中不指定任何异常类  
但是还将捕获Ctrl+C终止的企图。调用函数sys.exit来终止执行的企图等
```python
try:
    x = int(input('Enter the first number: '))
    y = int(input('Enter the second number: '))
    print(x / y)
except:
    print('Something wrong happened ...')
```
最好的方式是使用`except Exception as e`
```python
try:
    x = int(input('Enter the first number: '))
    y = int(input('Enter the second number: '))
    print(x / y)
except Exception as e:
    print(e)
    print('Something wrong happened ...')
```
### 8.3.6 万事大吉时
可以添加一个else子句，在没有出现异常的时候执行
```python
while True:
    try:
        x = int(input('请输入x：'))
        y = int(input('请输入y：'))
        value = x / y
        print('x/y is', value)
    except Exception as e:
        print("非法输入:", e)
        print('请重新操作')
    else:
        break
```
### 8.3.7 最后 finally
finally子句，可用于在发生异常时执行清理工作。  
finally子句非常适合用于确保文件或网络套接字等得以关闭
```python
x = None
try:
    x = 1/0
finally:
    print("finally")
    del x
```

## 8.4 异常和函数
如果不处理函数中引发的异常，那么就会向上传播到函数的调用方。如果函数调用方也不处理
那就会接着向上传播，直到到达主程序。主程序不处理的话，程序将终止并显示栈跟踪消息。
```python
def faulty():
    raise Exception("Something is wrong")

def ignore_exception():
    faulty()

def handle_exception():
    try:
        faulty()
    except:
        print("Exception handled")

handle_exception()  # Exception handled



ignore_exception()
# Traceback (most recent call last):
#   File "E:/zjx/PycharmProjects/LearnPython/BeginningPython/chapter8/chapter8.py", line 146, in <module>
#     ignore_exception()
#   File "E:/zjx/PycharmProjects/LearnPython/BeginningPython/chapter8/chapter8.py", line 137, in ignore_exception
#     faulty()
#   File "E:/zjx/PycharmProjects/LearnPython/BeginningPython/chapter8/chapter8.py", line 134, in faulty
#     raise Exception("Something is wrong")
# Exception: Something is wrong
```

## 8.5 异常之禅
有时需要考虑用异常来提升代码效率
```python
# 不使用异常处理
person = {"name": "zjx", 'age': 26, "occupation": 'Tester'}

def describePerson(person):
    print("Description of", person['name'])
    print("Age:", person['age'])
    if 'occupation' in person:
        print('Occupation:', person['occupation'])
describePerson(person)
```
```python
# 使用异常处理来减少在person中查找occupation的次数
def describePerson2(person):
    print("Description of", person['name'])
    print("Age:", person['age'])
    try:
        print('Occupation:', person['occupation'])
    except KeyError:
        pass

person2 = {"name": "ckx", 'age': 26}
describePerson2(person2)
```
利用异常处理检查对象是否包含特定属性
```python
try:
    obj.write
except AttributeError:
    print('The object is not writable')
else:
    print('The object is writeable')
```
Python的风格是推荐使用try/catch语句。
## 8.6 不那么异常的情况
通过warning模块中的warn来发出警告
```python
from warnings import warn, filterwarnings

warn("我只是警告一下")
```
可以用函数filterwarnings来抑制发出的警告 比如采取error或ignore
```python
filterwarnings("ignore")
warn("我试试是不是被ignore了") #没有输出

filterwarnings('error')
warn("我被处理成error")
# Traceback (most recent call last):
#   File "/Users/zjx/PycharmProjects/LearnPython/BeginningPython/chapter8/chapter8.py", line 194, in <module>
#     warn("我被处理成error")
# UserWarning: 我被处理成error

```
根据异常来过滤掉特定类型的警告
```python
filterwarnings("error")
warn("This function is really old...", DeprecationWarning)  # 正常输出为异常

filterwarnings("ignore", category=DeprecationWarning)
warn("Another deprecation warning.", DeprecationWarning)  # 不会输出，被过滤了
warn("Something else.")  # 正常输出
```